<?xml version="1.0"?>
<robot name="easyrobot">
  <!-- Virtual Fixed Frame Link -->
  <link name="fixedFrame"/>
  <!-- Virtual Joint to fixate/move robot -->
  <joint name="fixedFrameToWorld" type="fixed">
    <parent link="fixedFrame"/>
    <child link="base"/>
    <origin rpy="0 0 0" xyz="0 0 0.5"/>
  </joint>
  
  <!--From here the easyrobot is defined-->
  <link name="base">
    <visual>
      <geometry>
        <box size="0.5 0.05 0.1"/>
      </geometry>
      <origin rpy="0 1.57 0" xyz="0 0 0.225"/>
    </visual>
    <collision>
      <geometry>
        <box size="0.5 0.05 0.1"/>
      </geometry>
      <origin rpy="0 1.57 0" xyz="0 0 0.225"/>
    </collision>
    <inertial>
      <mass value="1"/>
      <inertia ixx="1e-5" ixy="0.0" ixz="0.0" iyy="1e-5" iyz="0.0" izz="1e-5"/>
    </inertial>
  </link>
  
  <link name="link1">
    <visual>
      <geometry>
        <box size="0.5 0.05 0.1"/>
      </geometry>
      <origin rpy="0 1.57 0" xyz="0 0 0.225"/>
    </visual>
    <collision>
      <geometry>
        <box size="0.5 0.05 0.1"/>
      </geometry>
      <origin rpy="0 1.57 0" xyz="0 0 0.225"/>
    </collision>
    <inertial>
      <mass value="1"/>
      <inertia ixx="1e-5" ixy="0.0" ixz="0.0" iyy="1e-5" iyz="0.0" izz="1e-5"/>
    </inertial>
  </link>
  
  <link name="link2">
    <visual>
      <geometry>
        <box size="0.5 0.05 0.1"/>
      </geometry>
      <origin rpy="0 1.57 0" xyz="0 0 0.225"/>
    </visual>
    <collision>
      <geometry>
        <box size="0.5 0.05 0.1"/>
      </geometry>
      <origin rpy="0 1.57 0" xyz="0 0 0.225"/>
    </collision>
    <inertial>
      <mass value="1"/>
      <inertia ixx="1e-5" ixy="0.0" ixz="0.0" iyy="1e-5" iyz="0.0" izz="1e-5"/>
    </inertial>
  </link>
    
  <joint name="joint1" type="revolute">
    <parent link="base"/>
    <child link="link1"/>
    <origin
      xyz="0 0.05 0.45"
      rpy="0 0 0" />
    <axis
      xyz="0 1 0" />
    <limit
      lower="-3.141"
      upper="3.141"
      effort="1000"
      velocity="1000" />
  </joint>
  
  <joint name="joint2" type="revolute">
    <parent link="link1"/>
    <child link="link2"/>
    <origin
      xyz="0 0.05 0.45"
      rpy="0 0 0" />
    <axis
      xyz="0 1 0" />
    <limit
      lower="-3.141"
      upper="3.141"
      effort="1000"
      velocity="1000" />
  </joint>
  
  <!-- Virtual TCP Link and Joint to place it -->
  <link name="TCP"/>
  <joint name="link2ToTCP" type="fixed">
    <parent link="link2"/>
    <child link="TCP"/>
    <origin rpy="0 0 1.57" xyz="0 0 0.475"/>
  </joint>
  
  
  
  <transmission name="tran1">
    <type>transmission_interface/SimpleTransmission</type>
    <joint name="joint1">
      <hardwareInterface>hardware_interface/EffortJointInterface</hardwareInterface>
    </joint>
    <actuator name="motor1">
      <hardwareInterface>hardware_interface/EffortJointInterface</hardwareInterface>
      <mechanicalReduction>1</mechanicalReduction>
    </actuator>
  </transmission>

  <transmission name="tran2">
    <type>transmission_interface/SimpleTransmission</type>
    <joint name="joint2">
      <hardwareInterface>hardware_interface/EffortJointInterface</hardwareInterface>
    </joint>
    <actuator name="motor2">
      <hardwareInterface>hardware_interface/EffortJointInterface</hardwareInterface>
      <mechanicalReduction>1</mechanicalReduction>
    </actuator>
  </transmission>
  
  
</robot>
